<?xml version="1.0" encoding="utf-8"?>
<!-- This URDF was automatically created by SolidWorks to URDF Exporter! Originally created by Stephen Brawner (brawner@gmail.com) 
     Commit Version: 1.6.0-4-g7f85cfe  Build Version: 1.6.7995.38578
     For more information, please see http://wiki.ros.org/sw_urdf_exporter -->
<robot
  name="9_axis">
  <link
    name="base_link">
    <inertial>
      <origin
        xyz="0 0 0.189882215868279"
        rpy="0 0 0" />
      <mass
        value="139.592927487695" />
      <inertia
        ixx="0.0718448286204054"
        ixy="-0.00144581311013746"
        ixz="-0.000450491456620577"
        iyy="30495.9579404736"
        iyz="-1.37561240877077E-07"
        izz="30495.9613779575" />
    </inertial>
    <visual>
      <origin
        xyz="0 0 0"
        rpy="0 0 0" />
      <geometry>
        <mesh
          filename="package://9_axis/meshes/base_link.STL" />
      </geometry>
      <material
        name="gantry_base">
        <color
          rgba="0.22 0.33 0.47 1" />
      </material>
    </visual>
    <collision>
      <origin
        xyz="0 0 0"
        rpy="0 0 0" />
      <geometry>
        <mesh
          filename="package://9_axis/meshes/base_link.STL" />
      </geometry>
    </collision>
  </link>
  <link
    name="link_01">
    <inertial>
      <origin
        xyz="-11.170896628338 7.35022646647284 3.70138836356233"
        rpy="0 0 0" />
      <mass
        value="6671.43699211194" />
      <inertia
        ixx="71801.1150658574"
        ixy="-0.000275933137035324"
        ixz="-0.0221733289672927"
        iyy="743.223509157629"
        iyz="0.00397707975149331"
        izz="71976.645259892" />
    </inertial>
    <visual>
      <origin
        xyz="0 0 0"
        rpy="0 0 0" />
      <geometry>
        <mesh
          filename="package://9_axis/meshes/link_01.STL" />
      </geometry>
      <material
        name="gantry_x">
        <color
          rgba="0.18 0.45 0.62 1" />
      </material>
    </visual>
    <collision>
      <origin
        xyz="0 0 0"
        rpy="0 0 0" />
      <geometry>
        <mesh
          filename="package://9_axis/meshes/link_01.STL" />
      </geometry>
    </collision>
  </link>
  <joint
    name="pris01"
    type="prismatic">
    <origin
      xyz="0 0 0"
      rpy="0 0 0" />
    <parent
      link="base_link" />
    <child
      link="link_01" />
    <axis
      xyz="1 0 0" />
    <limit
      lower="0"
      upper="20"
      effort="1000"
      velocity="1" />
  </joint>
  <link
    name="link_02">
    <inertial>
      <origin
        xyz="-10.1182799564004 11.4807341899315 4.05525907141845"
        rpy="0 0 0" />
      <mass
        value="40.148559695801" />
      <inertia
        ixx="3.50908475657513"
        ixy="-0.000572217823650541"
        ixz="-0.00072569738282989"
        iyy="2.39803866900882"
        iyz="-1.15244160141528E-07"
        izz="1.20787043727926" />
    </inertial>
    <visual>
      <origin
        xyz="0 0 0"
        rpy="0 0 0" />
      <geometry>
        <mesh
          filename="package://9_axis/meshes/link_02.STL" />
      </geometry>
      <material
        name="gantry_y">
        <color
          rgba="0.12 0.55 0.55 1" />
      </material>
    </visual>
    <collision>
      <origin
        xyz="0 0 0"
        rpy="0 0 0" />
      <geometry>
        <mesh
          filename="package://9_axis/meshes/link_02.STL" />
      </geometry>
    </collision>
  </link>
  <joint
    name="pris02"
    type="prismatic">
    <origin
      xyz="0 0 0"
      rpy="0 0 0" />
    <parent
      link="link_01" />
    <child
      link="link_02" />
    <axis
      xyz="0 1 0" />
    <limit
      lower="-10"
      upper="2"
      effort="1000"
      velocity="1" />
  </joint>
  <link
    name="link_03">
    <inertial>
      <origin
        xyz="-10.0101635288307 11.2872845086796 4.31198477472196"
        rpy="0 0 0" />
      <mass
        value="241.92854140384" />
      <inertia
        ixx="324.34375572915"
        ixy="-4.45378052502678E-07"
        ixz="-8.02551938519573E-05"
        iyy="323.367190485032"
        iyz="2.88253358991836E-06"
        izz="2.53813839890082" />
    </inertial>
    <visual>
      <origin
        xyz="0 0 0"
        rpy="0 0 0" />
      <geometry>
        <mesh
          filename="package://9_axis/meshes/link_03.STL" />
      </geometry>
      <material
        name="gantry_z">
        <color
          rgba="0.08 0.62 0.42 1" />
      </material>
    </visual>
    <collision>
      <origin
        xyz="0 0 0"
        rpy="0 0 0" />
      <geometry>
        <mesh
          filename="package://9_axis/meshes/link_03.STL" />
      </geometry>
    </collision>
  </link>
  <joint
    name="pris03"
    type="prismatic">
    <origin
      xyz="0 0 0"
      rpy="0 0 0" />
    <parent
      link="link_02" />
    <child
      link="link_03" />
    <axis
      xyz="0 0 1" />
    <limit
      lower="0"
      upper="5"
      effort="1000"
      velocity="1" />
  </joint>
  <link
    name="robobase">
    <inertial>
      <origin
        xyz="0.00281411995995548 -0.000194531191696483 0.0195447591183241"
        rpy="0 0 0" />
      <mass
        value="0.526598652051908" />
      <inertia
        ixx="0.000629597562234121"
        ixy="-2.42038795119825E-08"
        ixz="3.21123416404004E-06"
        iyy="0.00086870537882105"
        iyz="2.45011996420414E-07"
        izz="0.00136278998388592" />
    </inertial>
    <visual>
      <origin
        xyz="0 0 0"
        rpy="0 0 0" />
      <geometry>
        <mesh
          filename="package://9_axis/meshes/robobase.STL" />
      </geometry>
      <material
        name="robot_base">
        <color
          rgba="0.20 0.20 0.22 1" />
      </material>
    </visual>
    <collision>
      <origin
        xyz="0 0 0"
        rpy="0 0 0" />
      <geometry>
        <mesh
          filename="package://9_axis/meshes/robobase.STL" />
      </geometry>
    </collision>
  </link>
  <joint
    name="robobase"
    type="fixed">
    <origin
      xyz="-10.008 11.286 2.3119"
      rpy="-3.1415 0 0" />
    <parent
      link="link_03" />
    <child
      link="robobase" />
    <axis
      xyz="0 0 0" />
  </joint>
  <link
    name="link04">
    <inertial>
      <origin
        xyz="-2.51857531862945E-07 0.00332256500839039 -0.00150902460016494"
        rpy="0 0 0" />
      <mass
        value="15.1346479444998" />
      <inertia
        ixx="0.0443031651788231"
        ixy="-2.81167524079918E-08"
        ixz="-4.0596826899028E-07"
        iyy="0.0430901762109995"
        iyz="1.43719449704964E-05"
        izz="0.0305221713846399" />
    </inertial>
    <visual>
      <origin
        xyz="0 0 0"
        rpy="0 0 0" />
      <geometry>
        <mesh
          filename="package://9_axis/meshes/link04.STL" />
      </geometry>
      <material
        name="arm_link">
        <color
          rgba="0.88 0.90 0.95 1" />
      </material>
    </visual>
    <collision>
      <origin
        xyz="0 0 0"
        rpy="0 0 0" />
      <geometry>
        <mesh
          filename="package://9_axis/meshes/link04.STL" />
      </geometry>
    </collision>
  </link>
  <joint
    name="revo04"
    type="revolute">
    <origin
      xyz="0 -0.00022535 0.12015"
      rpy="0 0 0" />
    <parent
      link="robobase" />
    <child
      link="link04" />
    <axis
      xyz="0 0 -1" />
    <limit
      lower="-6.2832"
      upper="6.2832"
      effort="200"
      velocity="3.14" />
  </joint>
  <link
    name="link05">
    <inertial>
      <origin
        xyz="0.215000100287162 6.43173034275968E-09 -0.143146610069182"
        rpy="0 0 0" />
      <mass
        value="45.8465918633366" />
      <inertia
        ixx="0.1037483140575"
        ixy="-5.87095025929926E-08"
        ixz="2.54282490391606E-07"
        iyy="0.240121009336192"
        iyz="2.15483178508248E-08"
        izz="0.212572501503178" />
    </inertial>
    <visual>
      <origin
        xyz="0 0 0"
        rpy="0 0 0" />
      <geometry>
        <mesh
          filename="package://9_axis/meshes/link05.STL" />
      </geometry>
      <material
        name="arm_joint">
        <color
          rgba="0.95 0.55 0.10 1" />
      </material>
    </visual>
    <collision>
      <origin
        xyz="0 0 0"
        rpy="0 0 0" />
      <geometry>
        <mesh
          filename="package://9_axis/meshes/link05.STL" />
      </geometry>
    </collision>
  </link>
  <joint
    name="revo05"
    type="revolute">
    <origin
      xyz="0 0 0"
      rpy="1.5708 0 0" />
    <parent
      link="link04" />
    <child
      link="link05" />
    <axis
      xyz="0 0 1" />
    <limit
      lower="-6.2832"
      upper="6.2832"
      effort="200"
      velocity="3.14" />
  </joint>
  <link
    name="link06">
    <inertial>
      <origin
        xyz="0.190735496583493 -1.52687675682717E-05 -0.0106365862195608"
        rpy="0 0 0" />
      <mass
        value="18.0534564554839" />
      <inertia
        ixx="0.0197914204709761"
        ixy="6.48612971204404E-07"
        ixz="-0.0162800799758652"
        iyy="0.168630223367361"
        iyz="3.37641397447918E-07"
        izz="0.16527336838242" />
    </inertial>
    <visual>
      <origin
        xyz="0 0 0"
        rpy="0 0 0" />
      <geometry>
        <mesh
          filename="package://9_axis/meshes/link06.STL" />
      </geometry>
      <material
        name="arm_link2">
        <color
          rgba="0.88 0.90 0.95 1" />
      </material>
    </visual>
    <collision>
      <origin
        xyz="0 0 0"
        rpy="0 0 0" />
      <geometry>
        <mesh
          filename="package://9_axis/meshes/link06.STL" />
      </geometry>
    </collision>
  </link>
  <joint
    name="revo06"
    type="revolute">
    <origin
      xyz="0.43 0 0"
      rpy="0 0 0" />
    <parent
      link="link05" />
    <child
      link="link06" />
    <axis
      xyz="0 0 1" />
    <limit
      lower="-6.2832"
      upper="6.2832"
      effort="200"
      velocity="3.14" />
  </joint>
  <link
    name="link07">
    <inertial>
      <origin
        xyz="-1.98734804579548E-06 -0.00595118756440464 0.00267886074216196"
        rpy="0 0 0" />
      <mass
        value="5.53782702890545" />
      <inertia
        ixx="0.00708415707773477"
        ixy="1.83211236329591E-07"
        ixz="-2.36169851115656E-08"
        iyy="0.00516123063669001"
        iyz="-0.000397739879929697"
        izz="0.00684324625577803" />
    </inertial>
    <visual>
      <origin
        xyz="0 0 0"
        rpy="0 0 0" />
      <geometry>
        <mesh
          filename="package://9_axis/meshes/link07.STL" />
      </geometry>
      <material
        name="arm_joint2">
        <color
          rgba="0.95 0.55 0.10 1" />
      </material>
    </visual>
    <collision>
      <origin
        xyz="0 0 0"
        rpy="0 0 0" />
      <geometry>
        <mesh
          filename="package://9_axis/meshes/link07.STL" />
      </geometry>
    </collision>
  </link>
  <joint
    name="revo07"
    type="revolute">
    <origin
      xyz="0.3685 -1.185E-05 -0.114"
      rpy="0 0 0" />
    <parent
      link="link06" />
    <child
      link="link07" />
    <axis
      xyz="0 0 -1" />
    <limit
      lower="-6.2832"
      upper="6.2832"
      effort="200"
      velocity="3.14" />
  </joint>
  <link
    name="link08">
    <inertial>
      <origin
        xyz="-1.90944871258925E-06 -0.00288907759425719 -0.00234237394169147"
        rpy="0 0 0" />
      <mass
        value="6.33394466548073" />
      <inertia
        ixx="0.012920396120737"
        ixy="-1.08659585912681E-07"
        ixz="5.89055788634786E-09"
        iyy="0.00584529345673904"
        iyz="4.29603782509824E-05"
        izz="0.0126275585433332" />
    </inertial>
    <visual>
      <origin
        xyz="0 0 0"
        rpy="0 0 0" />
      <geometry>
        <mesh
          filename="package://9_axis/meshes/link08.STL" />
      </geometry>
      <material
        name="arm_link3">
        <color
          rgba="0.88 0.90 0.95 1" />
      </material>
    </visual>
    <collision>
      <origin
        xyz="0 0 0"
        rpy="0 0 0" />
      <geometry>
        <mesh
          filename="package://9_axis/meshes/link08.STL" />
      </geometry>
    </collision>
  </link>
  <joint
    name="revo08"
    type="revolute">
    <origin
      xyz="0 -0.1135 0"
      rpy="1.5708 0 0" />
    <parent
      link="link07" />
    <child
      link="link08" />
    <axis
      xyz="0 0 1" />
    <limit
      lower="-6.2832"
      upper="6.2832"
      effort="200"
      velocity="3.14" />
  </joint>
  <link
    name="link09">
    <inertial>
      <origin
        xyz="2.76523161145681E-05 -1.34854737601593E-05 -0.021245060068734"
        rpy="0 0 0" />
      <mass
        value="1.41689125820954" />
      <inertia
        ixx="0.000713704897956401"
        ixy="-6.91164349011104E-07"
        ixz="-6.36734535409925E-07"
        iyy="0.000723626940396581"
        iyz="1.5890038073838E-06"
        izz="0.00112895600939514" />
    </inertial>
    <visual>
      <origin
        xyz="0 0 0"
        rpy="0 0 0" />
      <geometry>
        <mesh
          filename="package://9_axis/meshes/link09.STL" />
      </geometry>
      <material
        name="arm_ee">
        <color
          rgba="0.85 0.20 0.15 1" />
      </material>
    </visual>
    <collision>
      <origin
        xyz="0 0 0"
        rpy="0 0 0" />
      <geometry>
        <mesh
          filename="package://9_axis/meshes/link09.STL" />
      </geometry>
    </collision>
  </link>
  <joint
    name="revo09"
    type="revolute">
    <origin
      xyz="0 0.107 0"
      rpy="-1.5708 0 0" />
    <parent
      link="link08" />
    <child
      link="link09" />
    <axis
      xyz="0 0 1" />
    <limit
      lower="-6.2832"
      upper="6.2832"
      effort="200"
      velocity="3.14" />
  </joint>
</robot>